<?xml version="1.0"?>
<robot name="rr_manipulator">
  <!-- 첫 번째 링크 -->
  <link name="base_link"/>

  <!-- 첫 번째 조인트 (회전) -->
  <joint name="joint1" type="revolute">
    <parent link="base_link"/>
    <child link="link1"/>
    <origin xyz="0 0 0" rpy="0 0 0"/>
    <axis xyz="1 0 0"/>
    <limit lower="-3.14" upper="3.14" effort="10" velocity="1.0"/>
  </joint>

  <!-- 첫 번째 링크 -->
  <link name="link1">
    <visual>
      <origin xyz="0 0 0.5" rpy="0 0 0"/>
      <geometry>
        <cylinder radius="0.05" length="1.0"/>
      </geometry>
      <material name="blue">
        <color rgba="0 0 1 1"/>
      </material>
    </visual>
  </link>

  <!-- 두 번째 조인트 (회전) -->
  <joint name="joint2" type="revolute">
    <parent link="link1"/>
    <child link="link2"/>
    <origin xyz="0 0 1" rpy="0 0 0"/>
    <axis xyz="1 0 0"/>
    <limit lower="-3.14" upper="3.14" effort="10" velocity="1.0"/>
  </joint>

  <!-- 두 번째 링크 -->
  <link name="link2">
    <visual>
      <origin xyz="0 0 0.5" rpy="0 0 0"/>
      <geometry>
        <cylinder radius="0.05" length="1.0"/>
      </geometry>
      <material name="green">
        <color rgba="0 1 0 1"/>
      </material>
    </visual>
  </link>
</robot>
